{'question': 'Report 2023 Discover Financial Services Balance Sheet ', 'vectordb_args': "doc_date = to_date('2023-03-31','YYYY-MM-DD') "}
<Response [500]>
Traceback (most recent call last):
  File "/opt/conda/lib/python3.10/site-packages/requests/models.py", line 974, in json
    return complexjson.loads(self.text, **kwargs)
  File "/opt/conda/lib/python3.10/json/__init__.py", line 346, in loads
    return _default_decoder.decode(s)
  File "/opt/conda/lib/python3.10/json/decoder.py", line 337, in decode
    obj, end = self.raw_decode(s, idx=_w(s, 0).end())
  File "/opt/conda/lib/python3.10/json/decoder.py", line 355, in raw_decode
    raise JSONDecodeError("Expecting value", s, err.value) from None
json.decoder.JSONDecodeError: Expecting value: line 1 column 1 (char 0)

During handling of the above exception, another exception occurred:

Traceback (most recent call last):
  File "/home/ec2-user/databaserag/database-rag/lc_finance_assistant_api_client.py", line 24, in <module>
    j = response.json()
  File "/opt/conda/lib/python3.10/site-packages/requests/models.py", line 978, in json
    raise RequestsJSONDecodeError(e.msg, e.doc, e.pos)
requests.exceptions.JSONDecodeError: Expecting value: line 1 column 1 (char 0)
{'question': 'Report 2023 Discover Financial Services Balance Sheet ', 'vectordb_args': "doc_date = to_date('2023-06-30','YYYY-MM-DD') "}
<Response [500]>
Traceback (most recent call last):
  File "/opt/conda/lib/python3.10/site-packages/requests/models.py", line 974, in json
    return complexjson.loads(self.text, **kwargs)
  File "/opt/conda/lib/python3.10/json/__init__.py", line 346, in loads
    return _default_decoder.decode(s)
  File "/opt/conda/lib/python3.10/json/decoder.py", line 337, in decode
    obj, end = self.raw_decode(s, idx=_w(s, 0).end())
  File "/opt/conda/lib/python3.10/json/decoder.py", line 355, in raw_decode
    raise JSONDecodeError("Expecting value", s, err.value) from None
json.decoder.JSONDecodeError: Expecting value: line 1 column 1 (char 0)

During handling of the above exception, another exception occurred:

Traceback (most recent call last):
  File "/home/ec2-user/databaserag/database-rag/lc_finance_assistant_api_client.py", line 24, in <module>
    j = response.json()
  File "/opt/conda/lib/python3.10/site-packages/requests/models.py", line 978, in json
    raise RequestsJSONDecodeError(e.msg, e.doc, e.pos)
requests.exceptions.JSONDecodeError: Expecting value: line 1 column 1 (char 0)
{'question': 'Report 2023 Discover Financial Services Balance Sheet ', 'vectordb_args': "doc_date = to_date('2023-09-30','YYYY-MM-DD') "}
<Response [500]>
Traceback (most recent call last):
  File "/opt/conda/lib/python3.10/site-packages/requests/models.py", line 974, in json
    return complexjson.loads(self.text, **kwargs)
  File "/opt/conda/lib/python3.10/json/__init__.py", line 346, in loads
    return _default_decoder.decode(s)
  File "/opt/conda/lib/python3.10/json/decoder.py", line 337, in decode
    obj, end = self.raw_decode(s, idx=_w(s, 0).end())
  File "/opt/conda/lib/python3.10/json/decoder.py", line 355, in raw_decode
    raise JSONDecodeError("Expecting value", s, err.value) from None
json.decoder.JSONDecodeError: Expecting value: line 1 column 1 (char 0)

During handling of the above exception, another exception occurred:

Traceback (most recent call last):
  File "/home/ec2-user/databaserag/database-rag/lc_finance_assistant_api_client.py", line 24, in <module>
    j = response.json()
  File "/opt/conda/lib/python3.10/site-packages/requests/models.py", line 978, in json
    raise RequestsJSONDecodeError(e.msg, e.doc, e.pos)
requests.exceptions.JSONDecodeError: Expecting value: line 1 column 1 (char 0)
{'question': 'Report 2024 Discover Financial Services Balance Sheet ', 'vectordb_args': "to_char(doc_date,'YYYY') = '2024'"}
<Response [500]>
Traceback (most recent call last):
  File "/opt/conda/lib/python3.10/site-packages/requests/models.py", line 974, in json
    return complexjson.loads(self.text, **kwargs)
  File "/opt/conda/lib/python3.10/json/__init__.py", line 346, in loads
    return _default_decoder.decode(s)
  File "/opt/conda/lib/python3.10/json/decoder.py", line 337, in decode
    obj, end = self.raw_decode(s, idx=_w(s, 0).end())
  File "/opt/conda/lib/python3.10/json/decoder.py", line 355, in raw_decode
    raise JSONDecodeError("Expecting value", s, err.value) from None
json.decoder.JSONDecodeError: Expecting value: line 1 column 1 (char 0)

During handling of the above exception, another exception occurred:

Traceback (most recent call last):
  File "/home/ec2-user/databaserag/database-rag/lc_finance_assistant_api_client.py", line 24, in <module>
    j = response.json()
  File "/opt/conda/lib/python3.10/site-packages/requests/models.py", line 978, in json
    raise RequestsJSONDecodeError(e.msg, e.doc, e.pos)
requests.exceptions.JSONDecodeError: Expecting value: line 1 column 1 (char 0)
{'question': 'Report 2023 Discover Financial Services Balance Sheet ', 'vectordb_args': "doc_date = to_date('2023-09-30','YYYY-MM-DD') "}
<Response [200]>

      
{'question': 'Report 2024 Discover Financial Services Balance Sheet ', 'vectordb_args': "to_char(doc_date,'YYYY') = '2024'"}
<Response [200]>

      
{'question': 'Report 2023 Discover Financial Services Balance Sheet ', 'vectordb_args': "doc_date = to_date('2023-06-30','YYYY-MM-DD') "}
<Response [500]>
Traceback (most recent call last):
  File "/opt/conda/lib/python3.10/site-packages/requests/models.py", line 974, in json
    return complexjson.loads(self.text, **kwargs)
  File "/opt/conda/lib/python3.10/json/__init__.py", line 346, in loads
    return _default_decoder.decode(s)
  File "/opt/conda/lib/python3.10/json/decoder.py", line 337, in decode
    obj, end = self.raw_decode(s, idx=_w(s, 0).end())
  File "/opt/conda/lib/python3.10/json/decoder.py", line 355, in raw_decode
    raise JSONDecodeError("Expecting value", s, err.value) from None
json.decoder.JSONDecodeError: Expecting value: line 1 column 1 (char 0)

During handling of the above exception, another exception occurred:

Traceback (most recent call last):
  File "/home/ec2-user/databaserag/database-rag/lc_finance_assistant_api_client.py", line 24, in <module>
    j = response.json()
  File "/opt/conda/lib/python3.10/site-packages/requests/models.py", line 978, in json
    raise RequestsJSONDecodeError(e.msg, e.doc, e.pos)
requests.exceptions.JSONDecodeError: Expecting value: line 1 column 1 (char 0)
{'question': 'Report 2023 Discover Financial Services Balance Sheet ', 'vectordb_args': "doc_date = to_date('2023-03-31','YYYY-MM-DD') "}
<Response [200]>

       Based on the provided financial statement, the balance sheet of Discover Financial Services as of March 31, 2023, is as follows:

**Assets:**

1. Cash and cash equivalents: $10,130 million
2. Restricted cash: $33 million
3. Investment securities: $12,248 million
4. Loan receivables: $104,983 million
5. Allowance for credit losses: ($7,691) million
6. Net loan receivables: $104,983 million
7. Premises and equipment, net: $1,031 million
8. Goodwill: $255 million
9. Other assets: $4,381 million

**Total assets:** $133,061 million

**Liabilities:**

1. Deposits:
	* Interest-bearing deposit accounts: $94,319 million
	* Non-interest bearing deposit accounts: $1,421 million
	Total deposits: $95,740 million
2. Long-term borrowings: $18,163 million
3. Accrued expenses and other liabilities: $4,843 million

**Total liabilities:** $118,746 million

**Stockholders' equity:**

1. Common stock: $6 million
2. Preferred stock: $1,056 million
3. Additional paid-in capital: $4,493 million
4. Retained earnings: $29,292 million
5. Accumulated other comprehensive loss: ($235) million
6. Treasury stock, at cost: ($20,297) million

**Total stockholders' equity:** $14,315 million

**Total liabilities and stockholders' equity:** $133,061 million

Please note that this is an unaudited condensed consolidated balance sheet and may not include all the information required for a complete and comprehensive financial statement.
